Workbook

Sheet Сводка
A1: Воронка кровельщиков
A2: ="Положение дел на "&TEXT(TODAY(),"dd.mm.yyyy")&". Лист собирается сам из «Лидов»."
A4: в очереди | B4: написали | C4: в работе | D4: дел на сегодня | E4: просрочено | F4: молчат 3+ дня | G4: созвонов назначено | H4: клиентов
A5: =COUNTIF('Лиды'!$C$2:$C$2000,"Очередь") | B5: =COUNTA('Лиды'!$B$2:$B$2000)-COUNTIF('Лиды'!$C$2:$C$2000,"Очередь")-COUNTIF('Лиды'!$C$2:$C$2000,"Не писать") | C5: =COUNTIF('Лиды'!$C$2:$C$2000,"Ответил")+COUNTIF('Лиды'!$C$2:$C$2000,"Доработать")+COUNTIF('Лиды'!$C$2:$C$2000,"Перезвонить")+COUNTIF('Лиды'!$C$2:$C$2000,"Созвон") | D5: =COUNTIF('Лиды'!$F$2:$F$2000,"сегодня")+COUNTIF('Лиды'!$F$2:$F$2000,"укажи дату") | E5: =COUNTIF('Лиды'!$F$2:$F$2000,"просрочено") | F5: =COUNTIF('Лиды'!$F$2:$F$2000,"молчит*") | G5: =COUNTIF('Лиды'!$C$2:$C$2000,"Созвон") | H5: =COUNTIF('Лиды'!$C$2:$C$2000,"Клиент")
A7: Этапы и менеджеры
A8: Этап | B8: Всего | C8: Ильяс | D8: Зураб | E8: Тимурлан | F8: Без менеджера | G8: Доля
A9: Отправлено | B9: =COUNTIF('Лиды'!$C$2:$C$2000,"Отправлено") | C9: =COUNTIFS('Лиды'!$C$2:$C$2000,"Отправлено",'Лиды'!$D$2:$D$2000,"Ильяс") | D9: =COUNTIFS('Лиды'!$C$2:$C$2000,"Отправлено",'Лиды'!$D$2:$D$2000,"Зураб") | E9: =COUNTIFS('Лиды'!$C$2:$C$2000,"Отправлено",'Лиды'!$D$2:$D$2000,"Тимурлан") | F9: =B9-SUM(C9:E9) | G9: =REPT("█",IF(MAX($B$9:$B$16)=0,0,ROUND(B9/MAX($B$9:$B$16)*24,0)))
A10: Не ответил | B10: =COUNTIF('Лиды'!$C$2:$C$2000,"Не ответил") | C10: =COUNTIFS('Лиды'!$C$2:$C$2000,"Не ответил",'Лиды'!$D$2:$D$2000,"Ильяс") | D10: =COUNTIFS('Лиды'!$C$2:$C$2000,"Не ответил",'Лиды'!$D$2:$D$2000,"Зураб") | E10: =COUNTIFS('Лиды'!$C$2:$C$2000,"Не ответил",'Лиды'!$D$2:$D$2000,"Тимурлан") | F10: =B10-SUM(C10:E10) | G10: =REPT("█",IF(MAX($B$9:$B$16)=0,0,ROUND(B10/MAX($B$9:$B$16)*24,0)))
A11: Ответил | B11: =COUNTIF('Лиды'!$C$2:$C$2000,"Ответил") | C11: =COUNTIFS('Лиды'!$C$2:$C$2000,"Ответил",'Лиды'!$D$2:$D$2000,"Ильяс") | D11: =COUNTIFS('Лиды'!$C$2:$C$2000,"Ответил",'Лиды'!$D$2:$D$2000,"Зураб") | E11: =COUNTIFS('Лиды'!$C$2:$C$2000,"Ответил",'Лиды'!$D$2:$D$2000,"Тимурлан") | F11: =B11-SUM(C11:E11) | G11: =REPT("█",IF(MAX($B$9:$B$16)=0,0,ROUND(B11/MAX($B$9:$B$16)*24,0)))
A12: Доработать | B12: =COUNTIF('Лиды'!$C$2:$C$2000,"Доработать") | C12: =COUNTIFS('Лиды'!$C$2:$C$2000,"Доработать",'Лиды'!$D$2:$D$2000,"Ильяс") | D12: =COUNTIFS('Лиды'!$C$2:$C$2000,"Доработать",'Лиды'!$D$2:$D$2000,"Зураб") | E12: =COUNTIFS('Лиды'!$C$2:$C$2000,"Доработать",'Лиды'!$D$2:$D$2000,"Тимурлан") | F12: =B12-SUM(C12:E12) | G12: =REPT("█",IF(MAX($B$9:$B$16)=0,0,ROUND(B12/MAX($B$9:$B$16)*24,0)))
A13: Перезвонить | B13: =COUNTIF('Лиды'!$C$2:$C$2000,"Перезвонить") | C13: =COUNTIFS('Лиды'!$C$2:$C$2000,"Перезвонить",'Лиды'!$D$2:$D$2000,"Ильяс") | D13: =COUNTIFS('Лиды'!$C$2:$C$2000,"Перезвонить",'Лиды'!$D$2:$D$2000,"Зураб") | E13: =COUNTIFS('Лиды'!$C$2:$C$2000,"Перезвонить",'Лиды'!$D$2:$D$2000,"Тимурлан") | F13: =B13-SUM(C13:E13) | G13: =REPT("█",IF(MAX($B$9:$B$16)=0,0,ROUND(B13/MAX($B$9:$B$16)*24,0)))
A14: Созвон | B14: =COUNTIF('Лиды'!$C$2:$C$2000,"Созвон") | C14: =COUNTIFS('Лиды'!$C$2:$C$2000,"Созвон",'Лиды'!$D$2:$D$2000,"Ильяс") | D14: =COUNTIFS('Лиды'!$C$2:$C$2000,"Созвон",'Лиды'!$D$2:$D$2000,"Зураб") | E14: =COUNTIFS('Лиды'!$C$2:$C$2000,"Созвон",'Лиды'!$D$2:$D$2000,"Тимурлан") | F14: =B14-SUM(C14:E14) | G14: =REPT("█",IF(MAX($B$9:$B$16)=0,0,ROUND(B14/MAX($B$9:$B$16)*24,0)))
A15: Клиент | B15: =COUNTIF('Лиды'!$C$2:$C$2000,"Клиент") | C15: =COUNTIFS('Лиды'!$C$2:$C$2000,"Клиент",'Лиды'!$D$2:$D$2000,"Ильяс") | D15: =COUNTIFS('Лиды'!$C$2:$C$2000,"Клиент",'Лиды'!$D$2:$D$2000,"Зураб") | E15: =COUNTIFS('Лиды'!$C$2:$C$2000,"Клиент",'Лиды'!$D$2:$D$2000,"Тимурлан") | F15: =B15-SUM(C15:E15) | G15: =REPT("█",IF(MAX($B$9:$B$16)=0,0,ROUND(B15/MAX($B$9:$B$16)*24,0)))
A16: Отказ | B16: =COUNTIF('Лиды'!$C$2:$C$2000,"Отказ") | C16: =COUNTIFS('Лиды'!$C$2:$C$2000,"Отказ",'Лиды'!$D$2:$D$2000,"Ильяс") | D16: =COUNTIFS('Лиды'!$C$2:$C$2000,"Отказ",'Лиды'!$D$2:$D$2000,"Зураб") | E16: =COUNTIFS('Лиды'!$C$2:$C$2000,"Отказ",'Лиды'!$D$2:$D$2000,"Тимурлан") | F16: =B16-SUM(C16:E16) | G16: =REPT("█",IF(MAX($B$9:$B$16)=0,0,ROUND(B16/MAX($B$9:$B$16)*24,0)))
A17: Всего в воронке | B17: =SUM(B9:B16) | C17: =SUM(C9:C16) | D17: =SUM(D9:D16) | E17: =SUM(E9:E16) | F17: =SUM(F9:F16)
A19: Конверсия
A20: Шаг | B20: Лидов | C20: От написанных
A21: Написали | B21: =B5 | C21: =IF($B$21=0,"—",B21/$B$21)
A22: Ответили | B22: =COUNTIF('Лиды'!$C$2:$C$2000,"Ответил")+COUNTIF('Лиды'!$C$2:$C$2000,"Доработать")+COUNTIF('Лиды'!$C$2:$C$2000,"Перезвонить")+COUNTIF('Лиды'!$C$2:$C$2000,"Созвон")+COUNTIF('Лиды'!$C$2:$C$2000,"Клиент")+COUNTIF('Лиды'!$C$2:$C$2000,"Отказ") | C22: =IF($B$21=0,"—",B22/$B$21)
A23: Созвон или клиент | B23: =COUNTIF('Лиды'!$C$2:$C$2000,"Созвон")+COUNTIF('Лиды'!$C$2:$C$2000,"Клиент") | C23: =IF($B$21=0,"—",B23/$B$21)
A24: Клиенты | B24: =COUNTIF('Лиды'!$C$2:$C$2000,"Клиент") | C24: =IF($B$21=0,"—",B24/$B$21)
A26: Что сделать сейчас — на листе «Сегодня». Кто на каком этапе — на листе «Канбан».

Sheet Сегодня
A1: Сегодня
A2: Все дела команды: на сегодня, просроченные, без даты и те, кто молчит три дня. Сверху самые старые. Править — на листе «Лиды».
A4: Компания | B4: Этап | C4: Менеджер | D4: Следующий контакт | E4: Срок | F4: Заметка | G4: Телефон | H4: Написали | I4: ранг | J4: Чат
A5: =IFERROR(SORT(FILTER('Лиды'!$B$2:$J$2000,'Лиды'!$V$2:$V$2000=1),4,TRUE),"Дел нет") | J5: =IF(G5="","",HYPERLINK("https://wa.me/"&G5,"Открыть чат"))
J6: =IF(G6="","",HYPERLINK("https://wa.me/"&G6,"Открыть чат"))
J7: =IF(G7="","",HYPERLINK("https://wa.me/"&G7,"Открыть чат"))
J8: =IF(G8="","",HYPERLINK("https://wa.me/"&G8,"Открыть чат"))
J9: =IF(G9="","",HYPERLINK("https://wa.me/"&G9,"Открыть чат"))
J10: =IF(G10="","",HYPERLINK("https://wa.me/"&G10,"Открыть чат"))
J11: =IF(G11="","",HYPERLINK("https://wa.me/"&G11,"Открыть чат"))
J12: =IF(G12="","",HYPERLINK("https://wa.me/"&G12,"Открыть чат"))
J13: =IF(G13="","",HYPERLINK("https://wa.me/"&G13,"Открыть чат"))
J14: =IF(G14="","",HYPERLINK("https://wa.me/"&G14,"Открыть чат"))
J15: =IF(G15="","",HYPERLINK("https://wa.me/"&G15,"Открыть чат"))
J16: =IF(G16="","",HYPERLINK("https://wa.me/"&G16,"Открыть чат"))
J17: =IF(G17="","",HYPERLINK("https://wa.me/"&G17,"Открыть чат"))
... J204: =IF(G204="","",HYPERLINK("https://wa.me/"&G204,"Открыть чат"))

Sheet Канбан
A1: Канбан
A2: Кто на каком этапе. В карточке: компания · менеджер, ниже срок. Этап меняется на листе «Лиды».
A4: ="Отправлено · "&COUNTIF('Лиды'!$C$2:$C$2000,"Отправлено") | B4: ="Не ответил · "&COUNTIF('Лиды'!$C$2:$C$2000,"Не ответил") | C4: ="Ответил · "&COUNTIF('Лиды'!$C$2:$C$2000,"Ответил") | D4: ="Доработать · "&COUNTIF('Лиды'!$C$2:$C$2000,"Доработать") | E4: ="Перезвонить · "&COUNTIF('Лиды'!$C$2:$C$2000,"Перезвонить") | F4: ="Созвон · "&COUNTIF('Лиды'!$C$2:$C$2000,"Созвон") | G4: ="Клиент · "&COUNTIF('Лиды'!$C$2:$C$2000,"Клиент") | H4: ="Отказ · "&COUNTIF('Лиды'!$C$2:$C$2000,"Отказ")
A5: =IFERROR(FILTER('Лиды'!$U$2:$U$2000,'Лиды'!$C$2:$C$2000="Отправлено"),"—") | B5: =IFERROR(FILTER('Лиды'!$U$2:$U$2000,'Лиды'!$C$2:$C$2000="Не ответил"),"—") | C5: =IFERROR(FILTER('Лиды'!$U$2:$U$2000,'Лиды'!$C$2:$C$2000="Ответил"),"—") | D5: =IFERROR(FILTER('Лиды'!$U$2:$U$2000,'Лиды'!$C$2:$C$2000="Доработать"),"—") | E5: =IFERROR(FILTER('Лиды'!$U$2:$U$2000,'Лиды'!$C$2:$C$2000="Перезвонить"),"—") | F5: =IFERROR(FILTER('Лиды'!$U$2:$U$2000,'Лиды'!$C$2:$C$2000="Созвон"),"—") | G5: =IFERROR(FILTER('Лиды'!$U$2:$U$2000,'Лиды'!$C$2:$C$2000="Клиент"),"—") | H5: =IFERROR(FILTER('Лиды'!$U$2:$U$2000,'Лиды'!$C$2:$C$2000="Отказ"),"—")

Sheet Лиды
A1: № | B1: Компания | C1: Этап | D1: Менеджер | E1: Следующий контакт | F1: Срок | G1: Заметка | H1: Телефон | I1: Написали | J1: ранг | K1: Написать | L1: Чат | M1: Город | N1: Рейтинг | O1: Отзывов | P1: Сайт | Q1: Пометки | R1: Пачка | S1: Регион | T1: Текст первого сообщения | U1: карточка | V1: дело
A2: 1 | B2: Комфорт сервис | C2: Очередь | F2: =IF(OR(C2="",C2="Очередь",C2="Клиент",C2="Отказ",C2="Не писать"),"",IF(E2="",IF(AND(C2="Отправлено",I2<>"",TODAY()-INT(I2)>=3),"молчит "&(TODAY()-INT(I2))&" дн.",IF(OR(C2="Перезвонить",C2="Созвон"),"укажи дату","")),IF(INT(E2)<TODAY(),"просрочено",IF(INT(E2)=TODAY(),"сегодня",IF(INT(E2)=TODAY()+1,"завтра",TEXT(E2,"dd.mm")))))) | H2: 79952262199 | J2: =IFERROR(MATCH(C2,'Справка'!$A$12:$A$21,0),99) | K2: =HYPERLINK("https://wa.me/"&H2&"?text="&ENCODEURL(T2),"✉ Написать") | L2: =HYPERLINK("https://wa.me/"&H2,"Открыть чат") | M2: Краснодар | N2: 4.9 | O2: 279 | Q2: без сайта | R2: 1 | S2: Краснодарский край | T2: Здравствуйте! Искал в 2ГИС кровельные компании в Краснодаре и наткнулся на вас: отзывы хорошие, а сайта нет. Могу за вечер собрать для «Комфорт сервис» сайт и показать. Платить не нужно, пока не понравится. Собрать? | U2: =B2&IF(D2<>""," · "&D2,"")&IF(F2<>"",CHAR(10)&F2,"") | V2: =IF(OR(F2="просрочено",F2="сегодня",F2="укажи дату",LEFT(F2,6)="молчит"),1,0)
A3: 2 | B3: Мир кровли | C3: Очередь | F3: =IF(OR(C3="",C3="Очередь",C3="Клиент",C3="Отказ",C3="Не писать"),"",IF(E3="",IF(AND(C3="Отправлено",I3<>"",TODAY()-INT(I3)>=3),"молчит "&(TODAY()-INT(I3))&" дн.",IF(OR(C3="Перезвонить",C3="Созвон"),"укажи дату","")),IF(INT(E3)<TODAY(),"просрочено",IF(INT(E3)=TODAY(),"сегодня",IF(INT(E3)=TODAY()+1,"завтра",TEXT(E3,"dd.mm")))))) | H3: 79184429434 | J3: =IFERROR(MATCH(C3,'Справка'!$A$12:$A$21,0),99) | K3: =HYPERLINK("https://wa.me/"&H3&"?text="&ENCODEURL(T3),"✉ Написать") | L3: =HYPERLINK("https://wa.me/"&H3,"Открыть чат") | M3: Краснодар | N3: 5 | O3: 20 | Q3: без сайта | R3: 1 | S3: Краснодарский край | T3: Здравствуйте! Смотрел в 2ГИС, кто делает кровлю в Краснодаре. У «Мир кровли» хорошие отзывы, но сайта в карточке я не нашёл. Готов за вечер собрать сайт для «Мир кровли» и показать вам. Денег вперёд не беру. Собрать? | U3: =B3&IF(D3<>""," · "&D3,"")&IF(F3<>"",CHAR(10)&F3,"") | V3: =IF(OR(F3="просрочено",F3="сегодня",F3="укажи дату",LEFT(F3,6)="молчит"),1,0)
A4: 3 | B4: Дом под ключ | C4: Очередь | F4: =IF(OR(C4="",C4="Очередь",C4="Клиент",C4="Отказ",C4="Не писать"),"",IF(E4="",IF(AND(C4="Отправлено",I4<>"",TODAY()-INT(I4)>=3),"молчит "&(TODAY()-INT(I4))&" дн.",IF(OR(C4="Перезвонить",C4="Созвон"),"укажи дату","")),IF(INT(E4)<TODAY(),"просрочено",IF(INT(E4)=TODAY(),"сегодня",IF(INT(E4)=TODAY()+1,"завтра",TEXT(E4,"dd.mm")))))) | H4: 79180702263 | J4: =IFERROR(MATCH(C4,'Справка'!$A$12:$A$21,0),99) | K4: =HYPERLINK("https://wa.me/"&H4&"?text="&ENCODEURL(T4),"✉ Написать") | L4: =HYPERLINK("https://wa.me/"&H4,"Открыть чат") | M4: Краснодар | N4: 4.9 | O4: 9 | Q4: без сайта | R4: 1 | S4: Краснодарский край | T4: Здравствуйте! Нашёл вас в 2ГИС среди кровельных компаний в Краснодаре: оценки высокие, а сайта нет. Могу собрать сайт под «Дом под ключ» за вечер и показать. Не понравится — ничего не должны. Сделать? | U4: =B4&IF(D4<>""," · "&D4,"")&IF(F4<>"",CHAR(10)&F4,"") | V4: =IF(OR(F4="просрочено",F4="сегодня",F4="укажи дату",LEFT(F4,6)="молчит"),1,0)
A5: 4 | B5: Ван | C5: Созвон | E5: 46301.708 | F5: =IF(OR(C5="",C5="Очередь",C5="Клиент",C5="Отказ",C5="Не писать"),"",IF(E5="",IF(AND(C5="Отправлено",I5<>"",TODAY()-INT(I5)>=3),"молчит "&(TODAY()-INT(I5))&" дн.",IF(OR(C5="Перезвонить",C5="Созвон"),"укажи дату","")),IF(INT(E5)<TODAY(),"просрочено",IF(INT(E5)=TODAY(),"сегодня",IF(INT(E5)=TODAY()+1,"завтра",TEXT(E5,"dd.mm")))))) | G5: сделал сайт + надо подготовить презу | H5: 79180999091 | I5: 46301 | J5: =IFERROR(MATCH(C5,'Справка'!$A$12:$A$21,0),99) | K5: =HYPERLINK("https://wa.me/"&H5&"?text="&ENCODEURL(T5),"✉ Написать") | L5: =HYPERLINK("https://wa.me/"&H5,"Открыть чат") | M5: Краснодар | N5: 5 | O5: 7 | Q5: без сайта | R5: 1 | S5: Краснодарский край | T5: Здравствуйте! Искал в 2ГИС кровельные компании в Краснодаре и наткнулся на вас: отзывы хорошие, а сайта нет. Могу за вечер собрать для «Ван» сайт и показать. Платить не нужно, пока не понравится. Собрать? | U5: =B5&IF(D5<>""," · "&D5,"")&IF(F5<>"",CHAR(10)&F5,"") | V5: =IF(OR(F5="просрочено",F5="сегодня",F5="укажи дату",LEFT(F5,6)="молчит"),1,0)
A6: 5 | B6: Вентгазнадзор | C6: Очередь | F6: =IF(OR(C6="",C6="Очередь",C6="Клиент",C6="Отказ",C6="Не писать"),"",IF(E6="",IF(AND(C6="Отправлено",I6<>"",TODAY()-INT(I6)>=3),"молчит "&(TODAY()-INT(I6))&" дн.",IF(OR(C6="Перезвонить",C6="Созвон"),"укажи дату","")),IF(INT(E6)<TODAY(),"просрочено",IF(INT(E6)=TODAY(),"сегодня",IF(INT(E6)=TODAY()+1,"завтра",TEXT(E6,"dd.mm")))))) | H6: 79528773239 | J6: =IFERROR(MATCH(C6,'Справка'!$A$12:$A$21,0),99) | K6: =HYPERLINK("https://wa.me/"&H6&"?text="&ENCODEURL(T6),"✉ Написать") | L6: =HYPERLINK("https://wa.me/"&H6,"Открыть чат") | M6: Краснодар | N6: 3.7 | O6: 3 | Q6: без сайта | R6: 1 | S6: Краснодарский край | T6: Здравствуйте! Смотрел в 2ГИС, кто делает кровлю в Краснодаре, и нашёл «Вентгазнадзор». Сайта в карточке нет. Готов за вечер собрать сайт для «Вентгазнадзор» и показать вам. Денег вперёд не беру. Собрать? | U6: =B6&IF(D6<>""," · "&D6,"")&IF(F6<>"",CHAR(10)&F6,"") | V6: =IF(OR(F6="просрочено",F6="сегодня",F6="укажи дату",LEFT(F6,6)="молчит"),1,0)
A7: 6 | B7: Первый дом | C7: Очередь | F7: =IF(OR(C7="",C7="Очередь",C7="Клиент",C7="Отказ",C7="Не писать"),"",IF(E7="",IF(AND(C7="Отправлено",I7<>"",TODAY()-INT(I7)>=3),"молчит "&(TODAY()-INT(I7))&" дн.",IF(OR(C7="Перезвонить",C7="Созвон"),"укажи дату","")),IF(INT(E7)<TODAY(),"просрочено",IF(INT(E7)=TODAY(),"сегодня",IF(INT(E7)=TODAY()+1,"завтра",TEXT(E7,"dd.mm")))))) | H7: 79182121617 | J7: =IFERROR(MATCH(C7,'Справка'!$A$12:$A$21,0),99) | K7: =HYPERLINK("https://wa.me/"&H7&"?text="&ENCODEURL(T7),"✉ Написать") | L7: =HYPERLINK("https://wa.me/"&H7,"Открыть чат") | M7: Краснодар | N7: 5 | O7: 1 | Q7: без сайта | R7: 1 | S7: Краснодарский край | T7: Здравствуйте! Нашёл вас в 2ГИС среди кровельных компаний в Краснодаре, а сайта в карточке не нашёл. Могу собрать сайт под «Первый дом» за вечер и показать. Не понравится — ничего не должны. Сделать? | U7: =B7&IF(D7<>""," · "&D7,"")&IF(F7<>"",CHAR(10)&F7,"") | V7: =IF(OR(F7="просрочено",F7="сегодня",F7="укажи дату",LEFT(F7,6)="молчит"),1,0)
A8: 7 | B8: Кровля для вас | C8: Очередь | F8: =IF(OR(C8="",C8="Очередь",C8="Клиент",C8="Отказ",C8="Не писать"),"",IF(E8="",IF(AND(C8="Отправлено",I8<>"",TODAY()-INT(I8)>=3),"молчит "&(TODAY()-INT(I8))&" дн.",IF(OR(C8="Перезвонить",C8="Созвон"),"укажи дату","")),IF(INT(E8)<TODAY(),"просрочено",IF(INT(E8)=TODAY(),"сегодня",IF(INT(E8)=TODAY()+1,"завтра",TEXT(E8,"dd.mm")))))) | H8: 79604743388 | J8: =IFERROR(MATCH(C8,'Справка'!$A$12:$A$21,0),99) | K8: =HYPERLINK("https://wa.me/"&H8&"?text="&ENCODEURL(T8),"✉ Написать") | L8: =HYPERLINK("https://wa.me/"&H8,"Открыть чат") | M8: Краснодар | N8: 1 | O8: 1 | Q8: без сайта | R8: 1 | S8: Краснодарский край | T8: Здравствуйте! Искал в 2ГИС кровельные компании в Краснодаре и наткнулся на вас. Сайта в карточке не увидел. Могу за вечер собрать для «Кровля для вас» сайт и показать. Платить не нужно, пока не понравится. Собрать? | U8: =B8&IF(D8<>""," · "&D8,"")&IF(F8<>"",CHAR(10)&F8,"") | V8: =IF(OR(F8="просрочено",F8="сегодня",F8="укажи дату",LEFT(F8,6)="молчит"),1,0)
A9: 8 | B9: Монтажная компания | C9: Очередь | F9: =IF(OR(C9="",C9="Очередь",C9="Клиент",C9="Отказ",C9="Не писать"),"",IF(E9="",IF(AND(C9="Отправлено",I9<>"",TODAY()-INT(I9)>=3),"молчит "&(TODAY()-INT(I9))&" дн.",IF(OR(C9="Перезвонить",C9="Созвон"),"укажи дату","")),IF(INT(E9)<TODAY(),"просрочено",IF(INT(E9)=TODAY(),"сегодня",IF(INT(E9)=TODAY()+1,"завтра",TEXT(E9,"dd.mm")))))) | H9: 79531181340 | J9: =IFERROR(MATCH(C9,'Справка'!$A$12:$A$21,0),99) | K9: =HYPERLINK("https://wa.me/"&H9&"?text="&ENCODEURL(T9),"✉ Написать") | L9: =HYPERLINK("https://wa.me/"&H9,"Открыть чат") | M9: Краснодар | Q9: без сайта | R9: 1 | S9: Краснодарский край | T9: Здравствуйте! Смотрел в 2ГИС, кто делает кровлю в Краснодаре, и нашёл «Монтажная компания». Сайта в карточке нет. Готов за вечер собрать сайт для «Монтажная компания» и показать вам. Денег вперёд не беру. Собрать? | U9: =B9&IF(D9<>""," · "&D9,"")&IF(F9<>"",CHAR(10)&F9,"") | V9: =IF(OR(F9="просрочено",F9="сегодня",F9="укажи дату",LEFT(F9,6)="молчит"),1,0)
A10: 9 | B10: Ремонт по карману | C10: Очередь | F10: =IF(OR(C10="",C10="Очередь",C10="Клиент",C10="Отказ",C10="Не писать"),"",IF(E10="",IF(AND(C10="Отправлено",I10<>"",TODAY()-INT(I10)>=3),"молчит "&(TODAY()-INT(I10))&" дн.",IF(OR(C10="Перезвонить",C10="Созвон"),"укажи дату","")),IF(INT(E10)<TODAY(),"просрочено",IF(INT(E10)=TODAY(),"сегодня",IF(INT(E10)=TODAY()+1,"завтра",TEXT(E10,"dd.mm")))))) | H10: 79885222323 | J10: =IFERROR(MATCH(C10,'Справка'!$A$12:$A$21,0),99) | K10: =HYPERLINK("https://wa.me/"&H10&"?text="&ENCODEURL(T10),"✉ Написать") | L10: =HYPERLINK("https://wa.me/"&H10,"Открыть чат") | M10: Краснодар | Q10: без сайта | R10: 1 | S10: Краснодарский край | T10: Здравствуйте! Нашёл вас в 2ГИС среди кровельных компаний в Краснодаре, а сайта в карточке не нашёл. Могу собрать сайт под «Ремонт по карману» за вечер и показать. Не понравится — ничего не должны. Сделать? | U10: =B10&IF(D10<>""," · "&D10,"")&IF(F10<>"",CHAR(10)&F10,"") | V10: =IF(OR(F10="просрочено",F10="сегодня",F10="укажи дату",LEFT(F10,6)="молчит"),1,0)
A11: 10 | B11: Кс | C11: Очередь | F11: =IF(OR(C11="",C11="Очередь",C11="Клиент",C11="Отказ",C11="Не писать"),"",IF(E11="",IF(AND(C11="Отправлено",I11<>"",TODAY()-INT(I11)>=3),"молчит "&(TODAY()-INT(I11))&" дн.",IF(OR(C11="Перезвонить",C11="Созвон"),"укажи дату","")),IF(INT(E11)<TODAY(),"просрочено",IF(INT(E11)=TODAY(),"сегодня",IF(INT(E11)=TODAY()+1,"завтра",TEXT(E11,"dd.mm")))))) | H11: 79002450555 | J11: =IFERROR(MATCH(C11,'Справка'!$A$12:$A$21,0),99) | K11: =HYPERLINK("https://wa.me/"&H11&"?text="&ENCODEURL(T11),"✉ Написать") | L11: =HYPERLINK("https://wa.me/"&H11,"Открыть чат") | M11: Краснодар | Q11: без сайта | R11: 1 | S11: Краснодарский край | T11: Здравствуйте! Искал в 2ГИС кровельные компании в Краснодаре и наткнулся на вас. Сайта в карточке не увидел. Могу за вечер собрать для «Кс» сайт и показать. Платить не нужно, пока не понравится. Собрать? | U11: =B11&IF(D11<>""," · "&D11,"")&IF(F11<>"",CHAR(10)&F11,"") | V11: =IF(OR(F11="просрочено",F11="сегодня",F11="укажи дату",LEFT(F11,6)="молчит"),1,0)
A12: 11 | B12: Автономия | C12: Очередь | F12: =IF(OR(C12="",C12="Очередь",C12="Клиент",C12="Отказ",C12="Не писать"),"",IF(E12="",IF(AND(C12="Отправлено",I12<>"",TODAY()-INT(I12)>=3),"молчит "&(TODAY()-INT(I12))&" дн.",IF(OR(C12="Перезвонить",C12="Созвон"),"укажи дату","")),IF(INT(E12)<TODAY(),"просрочено",IF(INT(E12)=TODAY(),"сегодня",IF(INT(E12)=TODAY()+1,"завтра",TEXT(E12,"dd.mm")))))) | H12: 79284153444 | J12: =IFERROR(MATCH(C12,'Справка'!$A$12:$A$21,0),99) | K12: =HYPERLINK("https://wa.me/"&H12&"?text="&ENCODEURL(T12),"✉ Написать") | L12: =HYPERLINK("https://wa.me/"&H12,"Открыть чат") | M12: Краснодар | Q12: без сайта | R12: 1 | S12: Краснодарский край | T12: Здравствуйте! Смотрел в 2ГИС, кто делает кровлю в Краснодаре, и нашёл «Автономия». Сайта в карточке нет. Готов за вечер собрать сайт для «Автономия» и показать вам. Денег вперёд не беру. Собрать? | U12: =B12&IF(D12<>""," · "&D12,"")&IF(F12<>"",CHAR(10)&F12,"") | V12: =IF(OR(F12="просрочено",F12="сегодня",F12="укажи дату",LEFT(F12,6)="молчит"),1,0)
A13: 12 | B13: Жестяной цех | C13: Очередь | F13: =IF(OR(C13="",C13="Очередь",C13="Клиент",C13="Отказ",C13="Не писать"),"",IF(E13="",IF(AND(C13="Отправлено",I13<>"",TODAY()-INT(I13)>=3),"молчит "&(TODAY()-INT(I13))&" дн.",IF(OR(C13="Перезвонить",C13="Созвон"),"укажи дату","")),IF(INT(E13)<TODAY(),"просрочено",IF(INT(E13)=TODAY(),"сегодня",IF(INT(E13)=TODAY()+1,"завтра",TEXT(E13,"dd.mm")))))) | H13: 79034495732 | J13: =IFERROR(MATCH(C13,'Справка'!$A$12:$A$21,0),99) | K13: =HYPERLINK("https://wa.me/"&H13&"?text="&ENCODEURL(T13),"✉ Написать") | L13: =HYPERLINK("https://wa.me/"&H13,"Открыть чат") | M13: пгт Яблоновский | Q13: без сайта | R13: 1 | S13: Краснодарский край | T13: Здравствуйте! Нашёл вас в 2ГИС среди кровельных компаний в Яблоновском, а сайта в карточке не нашёл. Могу собрать сайт под «Жестяной цех» за вечер и показать. Не понравится — ничего не должны. Сделать? | U13: =B13&IF(D13<>""," · "&D13,"")&IF(F13<>"",CHAR(10)&F13,"") | V13: =IF(OR(F13="просрочено",F13="сегодня",F13="укажи дату",LEFT(F13,6)="молчит"),1,0)
A14: 13 | B14: Юнисила-Юг | C14: Очередь | F14: =IF(OR(C14="",C14="Очередь",C14="Клиент",C14="Отказ",C14="Не писать"),"",IF(E14="",IF(AND(C14="Отправлено",I14<>"",TODAY()-INT(I14)>=3),"молчит "&(TODAY()-INT(I14))&" дн.",IF(OR(C14="Перезвонить",C14="Созвон"),"укажи дату","")),IF(INT(E14)<TODAY(),"просрочено",IF(INT(E14)=TODAY(),"сегодня",IF(INT(E14)=TODAY()+1,"завтра",TEXT(E14,"dd.mm")))))) | H14: 79898078818 | J14: =IFERROR(MATCH(C14,'Справка'!$A$12:$A$21,0),99) | K14: =HYPERLINK("https://wa.me/"&H14&"?text="&ENCODEURL(T14),"✉ Написать") | L14: =HYPERLINK("https://wa.me/"&H14,"Открыть чат") | M14: Краснодар | Q14: без сайта | R14: 1 | S14: Краснодарский край | T14: Здравствуйте! Искал в 2ГИС кровельные компании в Краснодаре и наткнулся на вас. Сайта в карточке не увидел. Могу за вечер собрать для «Юнисила-Юг» сайт и показать. Платить не нужно, пока не понравится. Собрать? | U14: =B14&IF(D14<>""," · "&D14,"")&IF(F14<>"",CHAR(10)&F14,"") | V14: =IF(OR(F14="просрочено",F14="сегодня",F14="укажи дату",LEFT(F14,6)="молчит"),1,0)
A15: 14 | B15: Кровмонтажстрой | C15: Очередь | F15: =IF(OR(C15="",C15="Очередь",C15="Клиент",C15="Отказ",C15="Не писать"),"",IF(E15="",IF(AND(C15="Отправлено",I15<>"",TODAY()-INT(I15)>=3),"молчит "&(TODAY()-INT(I15))&" дн.",IF(OR(C15="Перезвонить",C15="Созвон"),"укажи дату","")),IF(INT(E15)<TODAY(),"просрочено",IF(INT(E15)=TODAY(),"сегодня",IF(INT(E15)=TODAY()+1,"завтра",TEXT(E15,"dd.mm")))))) | H15: 79298320555 | J15: =IFERROR(MATCH(C15,'Справка'!$A$12:$A$21,0),99) | K15: =HYPERLINK("https://wa.me/"&H15&"?text="&ENCODEURL(T15),"✉ Написать") | L15: =HYPERLINK("https://wa.me/"&H15,"Открыть чат") | M15: Краснодар | Q15: без сайта | R15: 1 | S15: Краснодарский край | T15: Здравствуйте! Смотрел в 2ГИС, кто делает кровлю в Краснодаре, и нашёл «Кровмонтажстрой». Сайта в карточке нет. Готов за вечер собрать сайт для «Кровмонтажстрой» и показать вам. Денег вперёд не беру. Собрать? | U15: =B15&IF(D15<>""," · "&D15,"")&IF(F15<>"",CHAR(10)&F15,"") | V15: =IF(OR(F15="просрочено",F15="сегодня",F15="укажи дату",LEFT(F15,6)="молчит"),1,0)
A16: 15 | B16: Строительно пожарная компания | C16: Очередь | F16: =IF(OR(C16="",C16="Очередь",C16="Клиент",C16="Отказ",C16="Не писать"),"",IF(E16="",IF(AND(C16="Отправлено",I16<>"",TODAY()-INT(I16)>=3),"молчит "&(TODAY()-INT(I16))&" дн.",IF(OR(C16="Перезвонить",C16="Созвон"),"укажи дату","")),IF(INT(E16)<TODAY(),"просрочено",IF(INT(E16)=TODAY(),"сегодня",IF(INT(E16)=TODAY()+1,"завтра",TEXT(E16,"dd.mm")))))) | H16: 79180857658 | J16: =IFERROR(MATCH(C16,'Справка'!$A$12:$A$21,0),99) | K16: =HYPERLINK("https://wa.me/"&H16&"?text="&ENCODEURL(T16),"✉ Написать") | L16: =HYPERLINK("https://wa.me/"&H16,"Открыть чат") | M16: Краснодар | Q16: без сайта | R16: 1 | S16: Краснодарский край | T16: Здравствуйте! Нашёл вас в 2ГИС среди кровельных компаний в Краснодаре, а сайта в карточке не нашёл. Могу собрать сайт под «Строительно пожарная компания» за вечер и показать. Не понравится — ничего не должны. Сделать? | U16: =B16&IF(D16<>""," · "&D16,"")&IF(F16<>"",CHAR(10)&F16,"") | V16: =IF(OR(F16="просрочено",F16="сегодня",F16="укажи дату",LEFT(F16,6)="молчит"),1,0)
A17: 16 | B17: КаспийСтрой-Юг | C17: Очередь | F17: =IF(OR(C17="",C17="Очередь",C17="Клиент",C17="Отказ",C17="Не писать"),"",IF(E17="",IF(AND(C17="Отправлено",I17<>"",TODAY()-INT(I17)>=3),"молчит "&(TODAY()-INT(I17))&" дн.",IF(OR(C17="Перезвонить",C17="Созвон"),"укажи дату","")),IF(INT(E17)<TODAY(),"просрочено",IF(INT(E17)=TODAY(),"сегодня",IF(INT(E17)=TODAY()+1,"завтра",TEXT(E17,"dd.mm")))))) | H17: 79885596464 | J17: =IFERROR(MATCH(C17,'Справка'!$A$12:$A$21,0),99) | K17: =HYPERLINK("https://wa.me/"&H17&"?text="&ENCODEURL(T17),"✉ Написать") | L17: =HYPERLINK("https://wa.me/"&H17,"Открыть чат") | M17: Краснодар | Q17: без сайта | R17: 1 | S17: Краснодарский край | T17: Здравствуйте! Искал в 2ГИС кровельные компании в Краснодаре и наткнулся на вас. Сайта в карточке не увидел. Могу за вечер собрать для «КаспийСтрой-Юг» сайт и показать. Платить не нужно, пока не понравится. Собрать? | U17: =B17&IF(D17<>""," · "&D17,"")&IF(F17<>"",CHAR(10)&F17,"") | V17: =IF(OR(F17="просрочено",F17="сегодня",F17="укажи дату",LEFT(F17,6)="молчит"),1,0)
A18: 17 | B18: Крепстрой | C18: Очередь | F18: =IF(OR(C18="",C18="Очередь",C18="Клиент",C18="Отказ",C18="Не писать"),"",IF(E18="",IF(AND(C18="Отправлено",I18<>"",TODAY()-INT(I18)>=3),"молчит "&(TODAY()-INT(I18))&" дн.",IF(OR(C18="Перезвонить",C18="Созвон"),"укажи дату","")),IF(INT(E18)<TODAY(),"просрочено",IF(INT(E18)=TODAY(),"сегодня",IF(INT(E18)=TODAY()+1,"завтра",TEXT(E18,"dd.mm")))))) | H18: 79965322817 | J18: =IFERROR(MATCH(C18,'Справка'!$A$12:$A$21,0),99) | K18: =HYPERLINK("https://wa.me/"&H18&"?text="&ENCODEURL(T18),"✉ Написать") | L18: =HYPERLINK("https://wa.me/"&H18,"Открыть чат") | M18: ст-ца Новотитаровская | Q18: без сайта | R18: 1 | S18: Краснодарский край | T18: Здравствуйте! Смотрел в 2ГИС, кто делает кровлю в Новотитаровской, и нашёл «Крепстрой». Сайта в карточке нет. Готов за вечер собрать сайт для «Крепстрой» и показать вам. Денег вперёд не беру. Собрать? | U18: =B18&IF(D18<>""," · "&D18,"")&IF(F18<>"",CHAR(10)&F18,"") | V18: =IF(OR(F18="просрочено",F18="сегодня",F18="укажи дату",LEFT(F18,6)="молчит"),1,0)
A19: 18 | B19: Фараон | C19: Очередь | F19: =IF(OR(C19="",C19="Очередь",C19="Клиент",C19="Отказ",C19="Не писать"),"",IF(E19="",IF(AND(C19="Отправлено",I19<>"",TODAY()-INT(I19)>=3),"молчит "&(TODAY()-INT(I19))&" дн.",IF(OR(C19="Перезвонить",C19="Созвон"),"укажи дату","")),IF(INT(E19)<TODAY(),"просрочено",IF(INT(E19)=TODAY(),"сегодня",IF(INT(E19)=TODAY()+1,"завтра",TEXT(E19,"dd.mm")))))) | H19: 79696603030 | J19: =IFERROR(MATCH(C19,'Справка'!$A$12:$A$21,0),99) | K19: =HYPERLINK("https://wa.me/"&H19&"?text="&ENCODEURL(T19),"✉ Написать") | L19: =HYPERLINK("https://wa.me/"&H19,"Открыть чат") | M19: Краснодар | N19: 5 | O19: 3 | Q19: без сайта, WhatsApp не подтверждён | R19: 1 | S19: Краснодарский край | T19: Здравствуйте! Нашёл вас в 2ГИС среди кровельных компаний в Краснодаре: оценки высокие, а сайта нет. Могу собрать сайт под «Фараон» за вечер и показать. Не понравится — ничего не должны. Сделать? | U19: =B19&IF(D19<>""," · "&D19,"")&IF(F19<>"",CHAR(10)&F19,"") | V19: =IF(OR(F19="просрочено",F19="сегодня",F19="укажи дату",LEFT(F19,6)="молчит"),1,0)
A20: 19 | B20: СК Белый ключ | C20: Очередь | F20: =IF(OR(C20="",C20="Очередь",C20="Клиент",C20="Отказ",C20="Не писать"),"",IF(E20="",IF(AND(C20="Отправлено",I20<>"",TODAY()-INT(I20)>=3),"молчит "&(TODAY()-INT(I20))&" дн.",IF(OR(C20="Перезвонить",C20="Созвон"),"укажи дату","")),IF(INT(E20)<TODAY(),"просрочено",IF(INT(E20)=TODAY(),"сегодня",IF(INT(E20)=TODAY()+1,"завтра",TEXT(E20,"dd.mm")))))) | H20: 79186850609 | J20: =IFERROR(MATCH(C20,'Справка'!$A$12:$A$21,0),99) | K20: =HYPERLINK("https://wa.me/"&H20&"?text="&ENCODEURL(T20),"✉ Написать") | L20: =HYPERLINK("https://wa.me/"&H20,"Открыть чат") | M20: Краснодар | N20: 4 | O20: 2 | Q20: без сайта, WhatsApp не подтверждён | R20: 1 | S20: Краснодарский край | T20: Здравствуйте! Искал в 2ГИС кровельные компании в Краснодаре и наткнулся на вас. Сайта в карточке не увидел. Могу за вечер собрать для «СК Белый ключ» сайт и показать. Платить не нужно, пока не понравится. Собрать? | U20: =B20&IF(D20<>""," · "&D20,"")&IF(F20<>"",CHAR(10)&F20,"") | V20: =IF(OR(F20="просрочено",F20="сегодня",F20="укажи дату",LEFT(F20,6)="молчит"),1,0)
A21: 20 | B21: СтройДом | C21: Очередь | F21: =IF(OR(C21="",C21="Очередь",C21="Клиент",C21="Отказ",C21="Не писать"),"",IF(E21="",IF(AND(C21="Отправлено",I21<>"",TODAY()-INT(I21)>=3),"молчит "&(TODAY()-INT(I21))&" дн.",IF(OR(C21="Перезвонить",C21="Созвон"),"укажи дату","")),IF(INT(E21)<TODAY(),"просрочено",IF(INT(E21)=TODAY(),"сегодня",IF(INT(E21)=TODAY()+1,"завтра",TEXT(E21,"dd.mm")))))) | H21: 79054043088 | J21: =IFERROR(MATCH(C21,'Справка'!$A$12:$A$21,0),99) | K21: =HYPERLINK("https://wa.me/"&H21&"?text="&ENCODEURL(T21),"✉ Написать") | L21: =HYPERLINK("https://wa.me/"&H21,"Открыть чат") | M21: Краснодар | N21: 5 | O21: 1 | Q21: без сайта, WhatsApp не подтверждён | R21: 1 | S21: Краснодарский край | T21: Здравствуйте! Смотрел в 2ГИС, кто делает кровлю в Краснодаре, и нашёл «СтройДом». Сайта в карточке нет. Готов за вечер собрать сайт для «СтройДом» и показать вам. Денег вперёд не беру. Собрать? | U21: =B21&IF(D21<>""," · "&D21,"")&IF(F21<>"",CHAR(10)&F21,"") | V21: =IF(OR(F21="просрочено",F21="сегодня",F21="укажи дату",LEFT(F21,6)="молчит"),1,0)
A22: 21 | B22: Строительная компания | C22: Очередь | F22: =IF(OR(C22="",C22="Очередь",C22="Клиент",C22="Отказ",C22="Не писать"),"",IF(E22="",IF(AND(C22="Отправлено",I22<>"",TODAY()-INT(I22)>=3),"молчит "&(TODAY()-INT(I22))&" дн.",IF(OR(C22="Перезвонить",C22="Созвон"),"укажи дату","")),IF(INT(E22)<TODAY(),"просрочено",IF(INT(E22)=TODAY(),"сегодня",IF(INT(E22)=TODAY()+1,"завтра",TEXT(E22,"dd.mm")))))) | H22: 79282038053 | J22: =IFERROR(MATCH(C22,'Справка'!$A$12:$A$21,0),99) | K22: =HYPERLINK("https://wa.me/"&H22&"?text="&ENCODEURL(T22),"✉ Написать") | L22: =HYPERLINK("https://wa.me/"&H22,"Открыть чат") | M22: Краснодар | Q22: без сайта, WhatsApp не подтверждён | R22: 1 | S22: Краснодарский край | T22: Здравствуйте! Нашёл вас в 2ГИС среди кровельных компаний в Краснодаре, а сайта в карточке не нашёл. Могу собрать сайт под «Строительная компания» за вечер и показать. Не понравится — ничего не должны. Сделать? | U22: =B22&IF(D22<>""," · "&D22,"")&IF(F22<>"",CHAR(10)&F22,"") | V22: =IF(OR(F22="просрочено",F22="сегодня",F22="укажи дату",LEFT(F22,6)="молчит"),1,0)
A23: 22 | B23: КровМонтаж | C23: Очередь | F23: =IF(OR(C23="",C23="Очередь",C23="Клиент",C23="Отказ",C23="Не писать"),"",IF(E23="",IF(AND(C23="Отправлено",I23<>"",TODAY()-INT(I23)>=3),"молчит "&(TODAY()-INT(I23))&" дн.",IF(OR(C23="Перезвонить",C23="Созвон"),"укажи дату","")),IF(INT(E23)<TODAY(),"просрочено",IF(INT(E23)=TODAY(),"сегодня",IF(INT(E23)=TODAY()+1,"завтра",TEXT(E23,"dd.mm")))))) | H23: 79136297117 | J23: =IFERROR(MATCH(C23,'Справка'!$A$12:$A$21,0),99) | K23: =HYPERLINK("https://wa.me/"&H23&"?text="&ENCODEURL(T23),"✉ Написать") | L23: =HYPERLINK("https://wa.me/"&H23,"Открыть чат") | M23: Краснодар | Q23: без сайта, WhatsApp не подтверждён | R23: 1 | S23: Краснодарский край | T23: Здравствуйте! Искал в 2ГИС кровельные компании в Краснодаре и наткнулся на вас. Сайта в карточке не увидел. Могу за вечер собрать для «КровМонтаж» сайт и показать. Платить не нужно, пока не понравится. Собрать? | U23: =B23&IF(D23<>""," · "&D23,"")&IF(F23<>"",CHAR(10)&F23,"") | V23: =IF(OR(F23="просрочено",F23="сегодня",F23="укажи дату",LEFT(F23,6)="молчит"),1,0)
A24: 23 | B24: Компания по кровельным работам | C24: Очередь | F24: =IF(OR(C24="",C24="Очередь",C24="Клиент",C24="Отказ",C24="Не писать"),"",IF(E24="",IF(AND(C24="Отправлено",I24<>"",TODAY()-INT(I24)>=3),"молчит "&(TODAY()-INT(I24))&" дн.",IF(OR(C24="Перезвонить",C24="Созвон"),"укажи дату","")),IF(INT(E24)<TODAY(),"просрочено",IF(INT(E24)=TODAY(),"сегодня",IF(INT(E24)=TODAY()+1,"завтра",TEXT(E24,"dd.mm")))))) | H24: 79183312345 | J24: =IFERROR(MATCH(C24,'Справка'!$A$12:$A$21,0),99) | K24: =HYPERLINK("https://wa.me/"&H24&"?text="&ENCODEURL(T24),"✉ Написать") | L24: =HYPERLINK("https://wa.me/"&H24,"Открыть чат") | M24: Краснодар | Q24: без сайта, WhatsApp не подтверждён | R24: 1 | S24: Краснодарский край | T24: Здравствуйте! Смотрел в 2ГИС, кто делает кровлю в Краснодаре, и нашёл «Компания по кровельным работам». Сайта в карточке нет. Готов за вечер собрать сайт для «Компания по кровельным работам» и показать вам. Денег вперёд не беру. Собрать? | U24: =B24&IF(D24<>""," · "&D24,"")&IF(F24<>"",CHAR(10)&F24,"") | V24: =IF(OR(F24="просрочено",F24="сегодня",F24="укажи дату",LEFT(F24,6)="молчит"),1,0)
A25: 24 | B25: Фирма по услугам кровельных работ | C25: Очередь | F25: =IF(OR(C25="",C25="Очередь",C25="Клиент",C25="Отказ",C25="Не писать"),"",IF(E25="",IF(AND(C25="Отправлено",I25<>"",TODAY()-INT(I25)>=3),"молчит "&(TODAY()-INT(I25))&" дн.",IF(OR(C25="Перезвонить",C25="Созвон"),"укажи дату","")),IF(INT(E25)<TODAY(),"просрочено",IF(INT(E25)=TODAY(),"сегодня",IF(INT(E25)=TODAY()+1,"завтра",TEXT(E25,"dd.mm")))))) | H25: 79183839805 | J25: =IFERROR(MATCH(C25,'Справка'!$A$12:$A$21,0),99) | K25: =HYPERLINK("https://wa.me/"&H25&"?text="&ENCODEURL(T25),"✉ Написать") | L25: =HYPERLINK("https://wa.me/"&H25,"Открыть чат") | M25: Краснодар | Q25: без сайта, WhatsApp не подтверждён | R25: 1 | S25: Краснодарский край | T25: Здравствуйте! Нашёл вас в 2ГИС среди кровельных компаний в Краснодаре, а сайта в карточке не нашёл. Могу собрать сайт под «Фирма по услугам кровельных работ» за вечер и показать. Не понравится — ничего не должны. Сделать? | U25: =B25&IF(D25<>""," · "&D25,"")&IF(F25<>"",CHAR(10)&F25,"") | V25: =IF(OR(F25="просрочено",F25="сегодня",F25="укажи дату",LEFT(F25,6)="молчит"),1,0)
A26: 25 | B26: Кровельная компания | C26: Очередь | F26: =IF(OR(C26="",C26="Очередь",C26="Клиент",C26="Отказ",C26="Не писать"),"",IF(E26="",IF(AND(C26="Отправлено",I26<>"",TODAY()-INT(I26)>=3),"молчит "&(TODAY()-INT(I26))&" дн.",IF(OR(C26="Перезвонить",C26="Созвон"),"укажи дату","")),IF(INT(E26)<TODAY(),"просрочено",IF(INT(E26)=TODAY(),"сегодня",IF(INT(E26)=TODAY()+1,"завтра",TEXT(E26,"dd.mm")))))) | H26: 79094605113 | J26: =IFERROR(MATCH(C26,'Справка'!$A$12:$A$21,0),99) | K26: =HYPERLINK("https://wa.me/"&H26&"?text="&ENCODEURL(T26),"✉ Написать") | L26: =HYPERLINK("https://wa.me/"&H26,"Открыть чат") | M26: Краснодар | Q26: без сайта, WhatsApp не подтверждён | R26: 1 | S26: Краснодарский край | T26: Здравствуйте! Искал в 2ГИС кровельные компании в Краснодаре и наткнулся на вас. Сайта в карточке не увидел. Могу за вечер собрать для «Кровельная компания» сайт и показать. Платить не нужно, пока не понравится. Собрать? | U26: =B26&IF(D26<>""," · "&D26,"")&IF(F26<>"",CHAR(10)&F26,"") | V26: =IF(OR(F26="просрочено",F26="сегодня",F26="укажи дату",LEFT(F26,6)="молчит"),1,0)
A27: 26 | B27: Компания кровельных работ | C27: Очередь | F27: =IF(OR(C27="",C27="Очередь",C27="Клиент",C27="Отказ",C27="Не писать"),"",IF(E27="",IF(AND(C27="Отправлено",I27<>"",TODAY()-INT(I27)>=3),"молчит "&(TODAY()-INT(I27))&" дн.",IF(OR(C27="Перезвонить",C27="Созвон"),"укажи дату","")),IF(INT(E27)<TODAY(),"просрочено",IF(INT(E27)=TODAY(),"сегодня",IF(INT(E27)=TODAY()+1,"завтра",TEXT(E27,"dd.mm")))))) | H27: 79034094281 | J27: =IFERROR(MATCH(C27,'Справка'!$A$12:$A$21,0),99) | K27: =HYPERLINK("https://wa.me/"&H27&"?text="&ENCODEURL(T27),"✉ Написать") | L27: =HYPERLINK("https://wa.me/"&H27,"Открыть чат") | M27: Краснодар | Q27: без сайта, WhatsApp не подтверждён | R27: 1 | S27: Краснодарский край | T27: Здравствуйте! Смотрел в 2ГИС, кто делает кровлю в Краснодаре, и нашёл «Компания кровельных работ». Сайта в карточке нет. Готов за вечер собрать сайт для «Компания кровельных работ» и показать вам. Денег вперёд не беру. Собрать? | U27: =B27&IF(D27<>""," · "&D27,"")&IF(F27<>"",CHAR(10)&F27,"") | V27: =IF(OR(F27="просрочено",F27="сегодня",F27="укажи дату",LEFT(F27,6)="молчит"),1,0)
A28: 27 | B28: Фирма по ремонту кровли | C28: Очередь | F28: =IF(OR(C28="",C28="Очередь",C28="Клиент",C28="Отказ",C28="Не писать"),"",IF(E28="",IF(AND(C28="Отправлено",I28<>"",TODAY()-INT(I28)>=3),"молчит "&(TODAY()-INT(I28))&" дн.",IF(OR(C28="Перезвонить",C28="Созвон"),"укажи дату","")),IF(INT(E28)<TODAY(),"просрочено",IF(INT(E28)=TODAY(),"сегодня",IF(INT(E28)=TODAY()+1,"завтра",TEXT(E28,"dd.mm")))))) | H28: 79184942546 | J28: =IFERROR(MATCH(C28,'Справка'!$A$12:$A$21,0),99) | K28: =HYPERLINK("https://wa.me/"&H28&"?text="&ENCODEURL(T28),"✉ Написать") | L28: =HYPERLINK("https://wa.me/"&H28,"Открыть чат") | M28: Краснодар | Q28: без сайта, WhatsApp не подтверждён | R28: 1 | S28: Краснодарский край | T28: Здравствуйте! Нашёл вас в 2ГИС среди кровельных компаний в Краснодаре, а сайта в карточке не нашёл. Могу собрать сайт под «Фирма по ремонту кровли» за вечер и показать. Не понравится — ничего не должны. Сделать? | U28: =B28&IF(D28<>""," · "&D28,"")&IF(F28<>"",CHAR(10)&F28,"") | V28: =IF(OR(F28="просрочено",F28="сегодня",F28="укажи дату",LEFT(F28,6)="молчит"),1,0)
A29: 28 | B29: Компания по кровельным работам | C29: Очередь | F29: =IF(OR(C29="",C29="Очередь",C29="Клиент",C29="Отказ",C29="Не писать"),"",IF(E29="",IF(AND(C29="Отправлено",I29<>"",TODAY()-INT(I29)>=3),"молчит "&(TODAY()-INT(I29))&" дн.",IF(OR(C29="Перезвонить",C29="Созвон"),"укажи дату","")),IF(INT(E29)<TODAY(),"просрочено",IF(INT(E29)=TODAY(),"сегодня",IF(INT(E29)=TODAY()+1,"завтра",TEXT(E29,"dd.mm")))))) | H29: 79307835680 | J29: =IFERROR(MATCH(C29,'Справка'!$A$12:$A$21,0),99) | K29: =HYPERLINK("https://wa.me/"&H29&"?text="&ENCODEURL(T29),"✉ Написать") | L29: =HYPERLINK("https://wa.me/"&H29,"Открыть чат") | M29: Краснодар | Q29: без сайта, WhatsApp не подтверждён | R29: 1 | S29: Краснодарский край | T29: Здравствуйте! Искал в 2ГИС кровельные компании в Краснодаре и наткнулся на вас. Сайта в карточке не увидел. Могу за вечер собрать для «Компания по кровельным работам» сайт и показать. Платить не нужно, пока не понравится. Собрать? | U29: =B29&IF(D29<>""," · "&D29,"")&IF(F29<>"",CHAR(10)&F29,"") | V29: =IF(OR(F29="просрочено",F29="сегодня",F29="укажи дату",LEFT(F29,6)="молчит"),1,0)
A30: 29 | B30: Выездная строительно-отделочная компания | C30: Очередь | F30: =IF(OR(C30="",C30="Очередь",C30="Клиент",C30="Отказ",C30="Не писать"),"",IF(E30="",IF(AND(C30="Отправлено",I30<>"",TODAY()-INT(I30)>=3),"молчит "&(TODAY()-INT(I30))&" дн.",IF(OR(C30="Перезвонить",C30="Созвон"),"укажи дату","")),IF(INT(E30)<TODAY(),"просрочено",IF(INT(E30)=TODAY(),"сегодня",IF(INT(E30)=TODAY()+1,"завтра",TEXT(E30,"dd.mm")))))) | H30: 79282311953 | J30: =IFERROR(MATCH(C30,'Справка'!$A$12:$A$21,0),99) | K30: =HYPERLINK("https://wa.me/"&H30&"?text="&ENCODEURL(T30),"✉ Написать") | L30: =HYPERLINK("https://wa.me/"&H30,"Открыть чат") | M30: Краснодар | Q30: без сайта, WhatsApp не подтверждён | R30: 1 | S30: Краснодарский край | T30: Здравствуйте! Смотрел в 2ГИС, кто делает кровлю в Краснодаре, и нашёл «Выездная строительно-отделочная компания». Сайта в карточке нет. Готов за вечер собрать сайт для «Выездная строительно-отделочная компания» и показать вам. Денег вперёд не беру. Собрать? | U30: =B30&IF(D30<>""," · "&D30,"")&IF(F30<>"",CHAR(10)&F30,"") | V30: =IF(OR(F30="просрочено",F30="сегодня",F30="укажи дату",LEFT(F30,6)="молчит"),1,0)
A31: 30 | B31: Строй-Комфорт | C31: Очередь | F31: =IF(OR(C31="",C31="Очередь",C31="Клиент",C31="Отказ",C31="Не писать"),"",IF(E31="",IF(AND(C31="Отправлено",I31<>"",TODAY()-INT(I31)>=3),"молчит "&(TODAY()-INT(I31))&" дн.",IF(OR(C31="Перезвонить",C31="Созвон"),"укажи дату","")),IF(INT(E31)<TODAY(),"просрочено",IF(INT(E31)=TODAY(),"сегодня",IF(INT(E31)=TODAY()+1,"завтра",TEXT(E31,"dd.mm")))))) | H31: 79384261313 | J31: =IFERROR(MATCH(C31,'Справка'!$A$12:$A$21,0),99) | K31: =HYPERLINK("https://wa.me/"&H31&"?text="&ENCODEURL(T31),"✉ Написать") | L31: =HYPERLINK("https://wa.me/"&H31,"Открыть чат") | M31: ст-ца Елизаветинская | N31: 5 | O31: 24 | P31: ск23.рф | Q31: есть сайт: сначала впиши в текст, что на нём не так | R31: 1 | S31: Краснодарский край | T31: Здравствуйте! Смотрел в 2ГИС кровельные компании в Елизаветинской, зашёл на ваш сайт с телефона: [ЧТО НЕ ТАК НА САЙТЕ]. Могу за вечер собрать вариант под «Строй-Комфорт», где это исправлено, и показать. Собрать? | U31: =B31&IF(D31<>""," · "&D31,"")&IF(F31<>"",CHAR(10)&F31,"") | V31: =IF(OR(F31="просрочено",F31="сегодня",F31="укажи дату",LEFT(F31,6)="молчит"),1,0)
A32: 31 | B32: Domont | C32: Очередь | F32: =IF(OR(C32="",C32="Очередь",C32="Клиент",C32="Отказ",C32="Не писать"),"",IF(E32="",IF(AND(C32="Отправлено",I32<>"",TODAY()-INT(I32)>=3),"молчит "&(TODAY()-INT(I32))&" дн.",IF(OR(C32="Перезвонить",C32="Созвон"),"укажи дату","")),IF(INT(E32)<TODAY(),"просрочено",IF(INT(E32)=TODAY(),"сегодня",IF(INT(E32)=TODAY()+1,"завтра",TEXT(E32,"dd.mm")))))) | H32: 79883882220 | J32: =IFERROR(MATCH(C32,'Справка'!$A$12:$A$21,0),99) | K32: =HYPERLINK("https://wa.me/"&H32&"?text="&ENCODEURL(T32),"✉ Написать") | L32: =HYPERLINK("https://wa.me/"&H32,"Открыть чат") | M32: Краснодар | N32: 4.7 | O32: 19 | P32: domontru.ru | Q32: есть сайт: сначала впиши в текст, что на нём не так | R32: 1 | S32: Краснодарский край | T32: Здравствуйте! Смотрел в 2ГИС кровельные компании в Краснодаре, зашёл на ваш сайт с телефона: [ЧТО НЕ ТАК НА САЙТЕ]. Могу за вечер собрать вариант под «Domont», где это исправлено, и показать. Собрать? | U32: =B32&IF(D32<>""," · "&D32,"")&IF(F32<>"",CHAR(10)&F32,"") | V32: =IF(OR(F32="просрочено",F32="сегодня",F32="укажи дату",LEFT(F32,6)="молчит"),1,0)
A33: 32 | B33: Кровельный цех | C33: Очередь | F33: =IF(OR(C33="",C33="Очередь",C33="Клиент",C33="Отказ",C33="Не писать"),"",IF(E33="",IF(AND(C33="Отправлено",I33<>"",TODAY()-INT(I33)>=3),"молчит "&(TODAY()-INT(I33))&" дн.",IF(OR(C33="Перезвонить",C33="Созвон"),"укажи дату","")),IF(INT(E33)<TODAY(),"просрочено",IF(INT(E33)=TODAY(),"сегодня",IF(INT(E33)=TODAY()+1,"завтра",TEXT(E33,"dd.mm")))))) | H33: 79676624699 | J33: =IFERROR(MATCH(C33,'Справка'!$A$12:$A$21,0),99) | K33: =HYPERLINK("https://wa.me/"&H33&"?text="&ENCODEURL(T33),"✉ Написать") | L33: =HYPERLINK("https://wa.me/"&H33,"Открыть чат") | M33: Краснодар | N33: 5 | O33: 19 | P33: master-krovla.ru | Q33: есть сайт: сначала впиши в текст, что на нём не так | R33: 1 | S33: Краснодарский край | T33: Здравствуйте! Смотрел в 2ГИС кровельные компании в Краснодаре, зашёл на ваш сайт с телефона: [ЧТО НЕ ТАК НА САЙТЕ]. Могу за вечер собрать вариант под «Кровельный цех», где это исправлено, и показать. Собрать? | U33: =B33&IF(D33<>""," · "&D33,"")&IF(F33<>"",CHAR(10)&F33,"") | V33: =IF(OR(F33="просрочено",F33="сегодня",F33="укажи дату",LEFT(F33,6)="молчит"),1,0)
A34: 33 | B34: Мастилит | C34: Очередь | F34: =IF(OR(C34="",C34="Очередь",C34="Клиент",C34="Отказ",C34="Не писать"),"",IF(E34="",IF(AND(C34="Отправлено",I34<>"",TODAY()-INT(I34)>=3),"молчит "&(TODAY()-INT(I34))&" дн.",IF(OR(C34="Перезвонить",C34="Созвон"),"укажи дату","")),IF(INT(E34)<TODAY(),"просрочено",IF(INT(E34)=TODAY(),"сегодня",IF(INT(E34)=TODAY()+1,"завтра",TEXT(E34,"dd.mm")))))) | H34: 79628513538 | J34: =IFERROR(MATCH(C34,'Справка'!$A$12:$A$21,0),99) | K34: =HYPERLINK("https://wa.me/"&H34&"?text="&ENCODEURL(T34),"✉ Написать") | L34: =HYPERLINK("https://wa.me/"&H34,"Открыть чат") | M34: Краснодар | N34: 5 | O34: 17 | P34: mastilit.ru | Q34: есть сайт: сначала впиши в текст, что на нём не так | R34: 1 | S34: Краснодарский край | T34: Здравствуйте! Смотрел в 2ГИС кровельные компании в Краснодаре, зашёл на ваш сайт с телефона: [ЧТО НЕ ТАК НА САЙТЕ]. Могу за вечер собрать вариант под «Мастилит», где это исправлено, и показать. Собрать? | U34: =B34&IF(D34<>""," · "&D34,"")&IF(F34<>"",CHAR(10)&F34,"") | V34: =IF(OR(F34="просрочено",F34="сегодня",F34="укажи дату",LEFT(F34,6)="молчит"),1,0)
A35: 34 | B35: СтройСит | C35: Очередь | F35: =IF(OR(C35="",C35="Очередь",C35="Клиент",C35="Отказ",C35="Не писать"),"",IF(E35="",IF(AND(C35="Отправлено",I35<>"",TODAY()-INT(I35)>=3),"молчит "&(TODAY()-INT(I35))&" дн.",IF(OR(C35="Перезвонить",C35="Созвон"),"укажи дату","")),IF(INT(E35)<TODAY(),"просрочено",IF(INT(E35)=TODAY(),"сегодня",IF(INT(E35)=TODAY()+1,"завтра",TEXT(E35,"dd.mm")))))) | H35: 79892201420 | J35: =IFERROR(MATCH(C35,'Справка'!$A$12:$A$21,0),99) | K35: =HYPERLINK("https://wa.me/"&H35&"?text="&ENCODEURL(T35),"✉ Написать") | L35: =HYPERLINK("https://wa.me/"&H35,"Открыть чат") | M35: Краснодар | N35: 5 | O35: 14 | P35: stroysit.ru | Q35: есть сайт: сначала впиши в текст, что на нём не так | R35: 1 | S35: Краснодарский край | T35: Здравствуйте! Смотрел в 2ГИС кровельные компании в Краснодаре, зашёл на ваш сайт с телефона: [ЧТО НЕ ТАК НА САЙТЕ]. Могу за вечер собрать вариант под «СтройСит», где это исправлено, и показать. Собрать? | U35: =B35&IF(D35<>""," · "&D35,"")&IF(F35<>"",CHAR(10)&F35,"") | V35: =IF(OR(F35="просрочено",F35="сегодня",F35="укажи дату",LEFT(F35,6)="молчит"),1,0)
A36: 35 | B36: DomThermos | C36: Очередь | F36: =IF(OR(C36="",C36="Очередь",C36="Клиент",C36="Отказ",C36="Не писать"),"",IF(E36="",IF(AND(C36="Отправлено",I36<>"",TODAY()-INT(I36)>=3),"молчит "&(TODAY()-INT(I36))&" дн.",IF(OR(C36="Перезвонить",C36="Созвон"),"укажи дату","")),IF(INT(E36)<TODAY(),"просрочено",IF(INT(E36)=TODAY(),"сегодня",IF(INT(E36)=TODAY()+1,"завтра",TEXT(E36,"dd.mm")))))) | H36: 79283326452 | J36: =IFERROR(MATCH(C36,'Справка'!$A$12:$A$21,0),99) | K36: =HYPERLINK("https://wa.me/"&H36&"?text="&ENCODEURL(T36),"✉ Написать") | L36: =HYPERLINK("https://wa.me/"&H36,"Открыть чат") | M36: Краснодар | N36: 4.9 | O36: 11 | P36: domthermos.ru | Q36: есть сайт: сначала впиши в текст, что на нём не так | R36: 1 | S36: Краснодарский край | T36: Здравствуйте! Смотрел в 2ГИС кровельные компании в Краснодаре, зашёл на ваш сайт с телефона: [ЧТО НЕ ТАК НА САЙТЕ]. Могу за вечер собрать вариант под «DomThermos», где это исправлено, и показать. Собрать? | U36: =B36&IF(D36<>""," · "&D36,"")&IF(F36<>"",CHAR(10)&F36,"") | V36: =IF(OR(F36="просрочено",F36="сегодня",F36="укажи дату",LEFT(F36,6)="молчит"),1,0)
A37: 36 | B37: МирСтрой | C37: Очередь | F37: =IF(OR(C37="",C37="Очередь",C37="Клиент",C37="Отказ",C37="Не писать"),"",IF(E37="",IF(AND(C37="Отправлено",I37<>"",TODAY()-INT(I37)>=3),"молчит "&(TODAY()-INT(I37))&" дн.",IF(OR(C37="Перезвонить",C37="Созвон"),"укажи дату","")),IF(INT(E37)<TODAY(),"просрочено",IF(INT(E37)=TODAY(),"сегодня",IF(INT(E37)=TODAY()+1,"завтра",TEXT(E37,"dd.mm")))))) | H37: 79933208200 | J37: =IFERROR(MATCH(C37,'Справка'!$A$12:$A$21,0),99) | K37: =HYPERLINK("https://wa.me/"&H37&"?text="&ENCODEURL(T37),"✉ Написать") | L37: =HYPERLINK("https://wa.me/"&H37,"Открыть чат") | M37: Краснодар | N37: 5 | O37: 8 | P37: mirstroyrus.ru | Q37: есть сайт: сначала впиши в текст, что на нём не так | R37: 1 | S37: Краснодарский край | T37: Здравствуйте! Смотрел в 2ГИС кровельные компании в Краснодаре, зашёл на ваш сайт с телефона: [ЧТО НЕ ТАК НА САЙТЕ]. Могу за вечер собрать вариант под «МирСтрой», где это исправлено, и показать. Собрать? | U37: =B37&IF(D37<>""," · "&D37,"")&IF(F37<>"",CHAR(10)&F37,"") | V37: =IF(OR(F37="просрочено",F37="сегодня",F37="укажи дату",LEFT(F37,6)="молчит"),1,0)
A38: 37 | B38: Кубанькровля | C38: Очередь | F38: =IF(OR(C38="",C38="Очередь",C38="Клиент",C38="Отказ",C38="Не писать"),"",IF(E38="",IF(AND(C38="Отправлено",I38<>"",TODAY()-INT(I38)>=3),"молчит "&(TODAY()-INT(I38))&" дн.",IF(OR(C38="Перезвонить",C38="Созвон"),"укажи дату","")),IF(INT(E38)<TODAY(),"просрочено",IF(INT(E38)=TODAY(),"сегодня",IF(INT(E38)=TODAY()+1,"завтра",TEXT(E38,"dd.mm")))))) | H38: 79528631434 | J38: =IFERROR(MATCH(C38,'Справка'!$A$12:$A$21,0),99) | K38: =HYPERLINK("https://wa.me/"&H38&"?text="&ENCODEURL(T38),"✉ Написать") | L38: =HYPERLINK("https://wa.me/"&H38,"Открыть чат") | M38: Краснодар | N38: 5 | O38: 3 | P38: кубанькровля.рф | Q38: есть сайт: сначала впиши в текст, что на нём не так | R38: 1 | S38: Краснодарский край | T38: Здравствуйте! Смотрел в 2ГИС кровельные компании в Краснодаре, зашёл на ваш сайт с телефона: [ЧТО НЕ ТАК НА САЙТЕ]. Могу за вечер собрать вариант под «Кубанькровля», где это исправлено, и показать. Собрать? | U38: =B38&IF(D38<>""," · "&D38,"")&IF(F38<>"",CHAR(10)&F38,"") | V38: =IF(OR(F38="просрочено",F38="сегодня",F38="укажи дату",LEFT(F38,6)="молчит"),1,0)
A39: 38 | B39: Краснодарская монтажная компания | C39: Очередь | F39: =IF(OR(C39="",C39="Очередь",C39="Клиент",C39="Отказ",C39="Не писать"),"",IF(E39="",IF(AND(C39="Отправлено",I39<>"",TODAY()-INT(I39)>=3),"молчит "&(TODAY()-INT(I39))&" дн.",IF(OR(C39="Перезвонить",C39="Созвон"),"укажи дату","")),IF(INT(E39)<TODAY(),"просрочено",IF(INT(E39)=TODAY(),"сегодня",IF(INT(E39)=TODAY()+1,"завтра",TEXT(E39,"dd.mm")))))) | H39: 79180095377 | J39: =IFERROR(MATCH(C39,'Справка'!$A$12:$A$21,0),99) | K39: =HYPERLINK("https://wa.me/"&H39&"?text="&ENCODEURL(T39),"✉ Написать") | L39: =HYPERLINK("https://wa.me/"&H39,"Открыть чат") | M39: Краснодар | N39: 5 | O39: 2 | P39: кмк23.рф | Q39: есть сайт: сначала впиши в текст, что на нём не так | R39: 1 | S39: Краснодарский край | T39: Здравствуйте! Смотрел в 2ГИС кровельные компании в Краснодаре, зашёл на ваш сайт с телефона: [ЧТО НЕ ТАК НА САЙТЕ]. Могу за вечер собрать вариант под «Краснодарская монтажная компания», где это исправлено, и показать. Собрать? | U39: =B39&IF(D39<>""," · "&D39,"")&IF(F39<>"",CHAR(10)&F39,"") | V39: =IF(OR(F39="просрочено",F39="сегодня",F39="укажи дату",LEFT(F39,6)="молчит"),1,0)
A40: 39 | B40: Лучший город | C40: Очередь | F40: =IF(OR(C40="",C40="Очередь",C40="Клиент",C40="Отказ",C40="Не писать"),"",IF(E40="",IF(AND(C40="Отправлено",I40<>"",TODAY()-INT(I40)>=3),"молчит "&(TODAY()-INT(I40))&" дн.",IF(OR(C40="Перезвонить",C40="Созвон"),"укажи дату","")),IF(INT(E40)<TODAY(),"просрочено",IF(INT(E40)=TODAY(),"сегодня",IF(INT(E40)=TODAY()+1,"завтра",TEXT(E40,"dd.mm")))))) | H40: 79323212579 | J40: =IFERROR(MATCH(C40,'Справка'!$A$12:$A$21,0),99) | K40: =HYPERLINK("https://wa.me/"&H40&"?text="&ENCODEURL(T40),"✉ Написать") | L40: =HYPERLINK("https://wa.me/"&H40,"Открыть чат") | M40: Краснодар | N40: 5 | O40: 1 | P40: psklg-dom.ru | Q40: есть сайт: сначала впиши в текст, что на нём не так | R40: 1 | S40: Краснодарский край | T40: Здравствуйте! Смотрел в 2ГИС кровельные компании в Краснодаре, зашёл на ваш сайт с телефона: [ЧТО НЕ ТАК НА САЙТЕ]. Могу за вечер собрать вариант под «Лучший город», где это исправлено, и показать. Собрать? | U40: =B40&IF(D40<>""," · "&D40,"")&IF(F40<>"",CHAR(10)&F40,"") | V40: =IF(OR(F40="просрочено",F40="сегодня",F40="укажи дату",LEFT(F40,6)="молчит"),1,0)
...

Sheet Ильяс
A1: Ильяс
A2: Твои дела и твои лиды. Лист собирается сам: править нужно на листе «Лиды».
A4: в работе | B4: ждём ответа | D4: дел на сегодня | E4: просрочено | G4: молчат 3+ дня | H4: клиентов
A5: =COUNTIFS('Лиды'!$C$2:$C$2000,"Ответил",'Лиды'!$D$2:$D$2000,$A$1)+COUNTIFS('Лиды'!$C$2:$C$2000,"Доработать",'Лиды'!$D$2:$D$2000,$A$1)+COUNTIFS('Лиды'!$C$2:$C$2000,"Перезвонить",'Лиды'!$D$2:$D$2000,$A$1)+COUNTIFS('Лиды'!$C$2:$C$2000,"Созвон",'Лиды'!$D$2:$D$2000,$A$1) | B5: =COUNTIFS('Лиды'!$C$2:$C$2000,"Отправлено",'Лиды'!$D$2:$D$2000,$A$1) | D5: =COUNTIFS('Лиды'!$F$2:$F$2000,"сегодня",'Лиды'!$D$2:$D$2000,$A$1)+COUNTIFS('Лиды'!$F$2:$F$2000,"укажи дату",'Лиды'!$D$2:$D$2000,$A$1) | E5: =COUNTIFS('Лиды'!$F$2:$F$2000,"просрочено",'Лиды'!$D$2:$D$2000,$A$1) | G5: =COUNTIFS('Лиды'!$F$2:$F$2000,"молчит*",'Лиды'!$D$2:$D$2000,$A$1) | H5: =COUNTIFS('Лиды'!$C$2:$C$2000,"Клиент",'Лиды'!$D$2:$D$2000,$A$1)
A7: Что сделать сейчас
A8: Компания | B8: Этап | C8: Менеджер | D8: Следующий контакт | E8: Срок | F8: Заметка | G8: Телефон | H8: Написали | I8: ранг | J8: Чат
A9: =IFERROR(ARRAY_CONSTRAIN(SORT(FILTER('Лиды'!$B$2:$J$2000,('Лиды'!$D$2:$D$2000=$A$1)*('Лиды'!$V$2:$V$2000=1)),4,TRUE),25,9),"Дел нет") | J9: =IF(G9="","",HYPERLINK("https://wa.me/"&G9,"Открыть чат"))
J10: =IF(G10="","",HYPERLINK("https://wa.me/"&G10,"Открыть чат"))
J11: =IF(G11="","",HYPERLINK("https://wa.me/"&G11,"Открыть чат"))
J12: =IF(G12="","",HYPERLINK("https://wa.me/"&G12,"Открыть чат"))
J13: =IF(G13="","",HYPERLINK("https://wa.me/"&G13,"Открыть чат"))
J14: =IF(G14="","",HYPERLINK("https://wa.me/"&G14,"Открыть чат"))
J15: =IF(G15="","",HYPERLINK("https://wa.me/"&G15,"Открыть чат"))
J16: =IF(G16="","",HYPERLINK("https://wa.me/"&G16,"Открыть чат"))
J17: =IF(G17="","",HYPERLINK("https://wa.me/"&G17,"Открыть чат"))
J18: =IF(G18="","",HYPERLINK("https://wa.me/"&G18,"Открыть чат"))
J19: =IF(G19="","",HYPERLINK("https://wa.me/"&G19,"Открыть чат"))
J20: =IF(G20="","",HYPERLINK("https://wa.me/"&G20,"Открыть чат"))
J21: =IF(G21="","",HYPERLINK("https://wa.me/"&G21,"Открыть чат"))
... J33: =IF(G33="","",HYPERLINK("https://wa.me/"&G33,"Открыть чат"))
A35: Все мои лиды по этапам
A36: Компания | B36: Этап | C36: Менеджер | D36: Следующий контакт | E36: Срок | F36: Заметка | G36: Телефон | H36: Написали | I36: ранг | J36: Чат
A37: =IFERROR(SORT(FILTER('Лиды'!$B$2:$J$2000,('Лиды'!$D$2:$D$2000=$A$1)*('Лиды'!$C$2:$C$2000<>"Очередь")),9,TRUE),"Пока никого: поставь себя в колонке «Менеджер» на листе «Лиды»") | J37: =IF(G37="","",HYPERLINK("https://wa.me/"&G37,"Открыть чат"))
J38: =IF(G38="","",HYPERLINK("https://wa.me/"&G38,"Открыть чат"))
J39: =IF(G39="","",HYPERLINK("https://wa.me/"&G39,"Открыть чат"))
J40: =IF(G40="","",HYPERLINK("https://wa.me/"&G40,"Открыть чат"))
J41: =IF(G41="","",HYPERLINK("https://wa.me/"&G41,"Открыть чат"))
J42: =IF(G42="","",HYPERLINK("https://wa.me/"&G42,"Открыть чат"))
J43: =IF(G43="","",HYPERLINK("https://wa.me/"&G43,"Открыть чат"))
J44: =IF(G44="","",HYPERLINK("https://wa.me/"&G44,"Открыть чат"))
J45: =IF(G45="","",HYPERLINK("https://wa.me/"&G45,"Открыть чат"))
J46: =IF(G46="","",HYPERLINK("https://wa.me/"&G46,"Открыть чат"))
J47: =IF(G47="","",HYPERLINK("https://wa.me/"&G47,"Открыть чат"))
J48: =IF(G48="","",HYPERLINK("https://wa.me/"&G48,"Открыть чат"))
J49: =IF(G49="","",HYPERLINK("https://wa.me/"&G49,"Открыть чат"))
... J336: =IF(G336="","",HYPERLINK("https://wa.me/"&G336,"Открыть чат"))

Sheet Зураб
A1: Зураб
A2: Твои дела и твои лиды. Лист собирается сам: править нужно на листе «Лиды».
A4: в работе | B4: ждём ответа | D4: дел на сегодня | E4: просрочено | G4: молчат 3+ дня | H4: клиентов
A5: =COUNTIFS('Лиды'!$C$2:$C$2000,"Ответил",'Лиды'!$D$2:$D$2000,$A$1)+COUNTIFS('Лиды'!$C$2:$C$2000,"Доработать",'Лиды'!$D$2:$D$2000,$A$1)+COUNTIFS('Лиды'!$C$2:$C$2000,"Перезвонить",'Лиды'!$D$2:$D$2000,$A$1)+COUNTIFS('Лиды'!$C$2:$C$2000,"Созвон",'Лиды'!$D$2:$D$2000,$A$1) | B5: =COUNTIFS('Лиды'!$C$2:$C$2000,"Отправлено",'Лиды'!$D$2:$D$2000,$A$1) | D5: =COUNTIFS('Лиды'!$F$2:$F$2000,"сегодня",'Лиды'!$D$2:$D$2000,$A$1)+COUNTIFS('Лиды'!$F$2:$F$2000,"укажи дату",'Лиды'!$D$2:$D$2000,$A$1) | E5: =COUNTIFS('Лиды'!$F$2:$F$2000,"просрочено",'Лиды'!$D$2:$D$2000,$A$1) | G5: =COUNTIFS('Лиды'!$F$2:$F$2000,"молчит*",'Лиды'!$D$2:$D$2000,$A$1) | H5: =COUNTIFS('Лиды'!$C$2:$C$2000,"Клиент",'Лиды'!$D$2:$D$2000,$A$1)
A7: Что сделать сейчас
A8: Компания | B8: Этап | C8: Менеджер | D8: Следующий контакт | E8: Срок | F8: Заметка | G8: Телефон | H8: Написали | I8: ранг | J8: Чат
A9: =IFERROR(ARRAY_CONSTRAIN(SORT(FILTER('Лиды'!$B$2:$J$2000,('Лиды'!$D$2:$D$2000=$A$1)*('Лиды'!$V$2:$V$2000=1)),4,TRUE),25,9),"Дел нет") | J9: =IF(G9="","",HYPERLINK("https://wa.me/"&G9,"Открыть чат"))
J10: =IF(G10="","",HYPERLINK("https://wa.me/"&G10,"Открыть чат"))
J11: =IF(G11="","",HYPERLINK("https://wa.me/"&G11,"Открыть чат"))
J12: =IF(G12="","",HYPERLINK("https://wa.me/"&G12,"Открыть чат"))
J13: =IF(G13="","",HYPERLINK("https://wa.me/"&G13,"Открыть чат"))
J14: =IF(G14="","",HYPERLINK("https://wa.me/"&G14,"Открыть чат"))
J15: =IF(G15="","",HYPERLINK("https://wa.me/"&G15,"Открыть чат"))
J16: =IF(G16="","",HYPERLINK("https://wa.me/"&G16,"Открыть чат"))
J17: =IF(G17="","",HYPERLINK("https://wa.me/"&G17,"Открыть чат"))
J18: =IF(G18="","",HYPERLINK("https://wa.me/"&G18,"Открыть чат"))
J19: =IF(G19="","",HYPERLINK("https://wa.me/"&G19,"Открыть чат"))
J20: =IF(G20="","",HYPERLINK("https://wa.me/"&G20,"Открыть чат"))
J21: =IF(G21="","",HYPERLINK("https://wa.me/"&G21,"Открыть чат"))
... J33: =IF(G33="","",HYPERLINK("https://wa.me/"&G33,"Открыть чат"))
A35: Все мои лиды по этапам
A36: Компания | B36: Этап | C36: Менеджер | D36: Следующий контакт | E36: Срок | F36: Заметка | G36: Телефон | H36: Написали | I36: ранг | J36: Чат
A37: =IFERROR(SORT(FILTER('Лиды'!$B$2:$J$2000,('Лиды'!$D$2:$D$2000=$A$1)*('Лиды'!$C$2:$C$2000<>"Очередь")),9,TRUE),"Пока никого: поставь себя в колонке «Менеджер» на листе «Лиды»") | J37: =IF(G37="","",HYPERLINK("https://wa.me/"&G37,"Открыть чат"))
J38: =IF(G38="","",HYPERLINK("https://wa.me/"&G38,"Открыть чат"))
J39: =IF(G39="","",HYPERLINK("https://wa.me/"&G39,"Открыть чат"))
J40: =IF(G40="","",HYPERLINK("https://wa.me/"&G40,"Открыть чат"))
J41: =IF(G41="","",HYPERLINK("https://wa.me/"&G41,"Открыть чат"))
J42: =IF(G42="","",HYPERLINK("https://wa.me/"&G42,"Открыть чат"))
J43: =IF(G43="","",HYPERLINK("https://wa.me/"&G43,"Открыть чат"))
J44: =IF(G44="","",HYPERLINK("https://wa.me/"&G44,"Открыть чат"))
J45: =IF(G45="","",HYPERLINK("https://wa.me/"&G45,"Открыть чат"))
J46: =IF(G46="","",HYPERLINK("https://wa.me/"&G46,"Открыть чат"))
J47: =IF(G47="","",HYPERLINK("https://wa.me/"&G47,"Открыть чат"))
J48: =IF(G48="","",HYPERLINK("https://wa.me/"&G48,"Открыть чат"))
J49: =IF(G49="","",HYPERLINK("https://wa.me/"&G49,"Открыть чат"))
... J336: =IF(G336="","",HYPERLINK("https://wa.me/"&G336,"Открыть чат"))

Sheet Тимурлан
A1: Тимурлан
A2: Твои дела и твои лиды. Лист собирается сам: править нужно на листе «Лиды».
A4: в работе | B4: ждём ответа | D4: дел на сегодня | E4: просрочено | G4: молчат 3+ дня | H4: клиентов
A5: =COUNTIFS('Лиды'!$C$2:$C$2000,"Ответил",'Лиды'!$D$2:$D$2000,$A$1)+COUNTIFS('Лиды'!$C$2:$C$2000,"Доработать",'Лиды'!$D$2:$D$2000,$A$1)+COUNTIFS('Лиды'!$C$2:$C$2000,"Перезвонить",'Лиды'!$D$2:$D$2000,$A$1)+COUNTIFS('Лиды'!$C$2:$C$2000,"Созвон",'Лиды'!$D$2:$D$2000,$A$1) | B5: =COUNTIFS('Лиды'!$C$2:$C$2000,"Отправлено",'Лиды'!$D$2:$D$2000,$A$1) | D5: =COUNTIFS('Лиды'!$F$2:$F$2000,"сегодня",'Лиды'!$D$2:$D$2000,$A$1)+COUNTIFS('Лиды'!$F$2:$F$2000,"укажи дату",'Лиды'!$D$2:$D$2000,$A$1) | E5: =COUNTIFS('Лиды'!$F$2:$F$2000,"просрочено",'Лиды'!$D$2:$D$2000,$A$1) | G5: =COUNTIFS('Лиды'!$F$2:$F$2000,"молчит*",'Лиды'!$D$2:$D$2000,$A$1) | H5: =COUNTIFS('Лиды'!$C$2:$C$2000,"Клиент",'Лиды'!$D$2:$D$2000,$A$1)
A7: Что сделать сейчас
A8: Компания | B8: Этап | C8: Менеджер | D8: Следующий контакт | E8: Срок | F8: Заметка | G8: Телефон | H8: Написали | I8: ранг | J8: Чат
A9: =IFERROR(ARRAY_CONSTRAIN(SORT(FILTER('Лиды'!$B$2:$J$2000,('Лиды'!$D$2:$D$2000=$A$1)*('Лиды'!$V$2:$V$2000=1)),4,TRUE),25,9),"Дел нет") | J9: =IF(G9="","",HYPERLINK("https://wa.me/"&G9,"Открыть чат"))
J10: =IF(G10="","",HYPERLINK("https://wa.me/"&G10,"Открыть чат"))
J11: =IF(G11="","",HYPERLINK("https://wa.me/"&G11,"Открыть чат"))
J12: =IF(G12="","",HYPERLINK("https://wa.me/"&G12,"Открыть чат"))
J13: =IF(G13="","",HYPERLINK("https://wa.me/"&G13,"Открыть чат"))
J14: =IF(G14="","",HYPERLINK("https://wa.me/"&G14,"Открыть чат"))
J15: =IF(G15="","",HYPERLINK("https://wa.me/"&G15,"Открыть чат"))
J16: =IF(G16="","",HYPERLINK("https://wa.me/"&G16,"Открыть чат"))
J17: =IF(G17="","",HYPERLINK("https://wa.me/"&G17,"Открыть чат"))
J18: =IF(G18="","",HYPERLINK("https://wa.me/"&G18,"Открыть чат"))
J19: =IF(G19="","",HYPERLINK("https://wa.me/"&G19,"Открыть чат"))
J20: =IF(G20="","",HYPERLINK("https://wa.me/"&G20,"Открыть чат"))
J21: =IF(G21="","",HYPERLINK("https://wa.me/"&G21,"Открыть чат"))
... J33: =IF(G33="","",HYPERLINK("https://wa.me/"&G33,"Открыть чат"))
A35: Все мои лиды по этапам
A36: Компания | B36: Этап | C36: Менеджер | D36: Следующий контакт | E36: Срок | F36: Заметка | G36: Телефон | H36: Написали | I36: ранг | J36: Чат
A37: =IFERROR(SORT(FILTER('Лиды'!$B$2:$J$2000,('Лиды'!$D$2:$D$2000=$A$1)*('Лиды'!$C$2:$C$2000<>"Очередь")),9,TRUE),"Пока никого: поставь себя в колонке «Менеджер» на листе «Лиды»") | J37: =IF(G37="","",HYPERLINK("https://wa.me/"&G37,"Открыть чат"))
J38: =IF(G38="","",HYPERLINK("https://wa.me/"&G38,"Открыть чат"))
J39: =IF(G39="","",HYPERLINK("https://wa.me/"&G39,"Открыть чат"))
J40: =IF(G40="","",HYPERLINK("https://wa.me/"&G40,"Открыть чат"))
J41: =IF(G41="","",HYPERLINK("https://wa.me/"&G41,"Открыть чат"))
J42: =IF(G42="","",HYPERLINK("https://wa.me/"&G42,"Открыть чат"))
J43: =IF(G43="","",HYPERLINK("https://wa.me/"&G43,"Открыть чат"))
J44: =IF(G44="","",HYPERLINK("https://wa.me/"&G44,"Открыть чат"))
J45: =IF(G45="","",HYPERLINK("https://wa.me/"&G45,"Открыть чат"))
J46: =IF(G46="","",HYPERLINK("https://wa.me/"&G46,"Открыть чат"))
J47: =IF(G47="","",HYPERLINK("https://wa.me/"&G47,"Открыть чат"))
J48: =IF(G48="","",HYPERLINK("https://wa.me/"&G48,"Открыть чат"))
J49: =IF(G49="","",HYPERLINK("https://wa.me/"&G49,"Открыть чат"))
... J336: =IF(G336="","",HYPERLINK("https://wa.me/"&G336,"Открыть чат"))

Sheet Справка
A1: Как пользоваться
